Workbook

Sheet Guide
B1: Timesheet 2026
B2: Log daily project hours against NTIME or P6. Unbooked hours become Overhead (Department Hours) automatically.
B4: How to use
B5: 1. | C5: Settings: check available hours per day (default 8), week start day, where overhead is booked, and overtime.
B6: 2. | C6: Projects: enter each project once (name, project number, Oracle code). They then appear in the dropdowns.
B7: 3. | C7: Month sheets: add one row per task in the Entry log - date, project (dropdown), task description, NTIME/P6, hours.
C8: Project number and Oracle code fill in automatically. The Check column flags anything missing or a day over its hours.
B9: 4. | C9: Daily summary (bottom right of each month): change Day type for leave, public holidays, or a day of only overhead.
B10: 5. | C10: Everything else is calculated: month KPIs, weekly summary and chart, projects this month, and the year dashboard.
B12: Rules
B13: Overhead | C13: On a Working day with project hours: overhead = available hours - project hours (never below 0).
C14: Example: Project A 4 h in NTIME + Project B 3 h in P6 = 7 h, so 1 h goes to Overhead.
B15: Overhead only | C15: Set Day type to 'Overhead only' for a working day with no project work: the whole day is overhead.
B16: Not logged | C16: A Working day up to today with no entries is shown as 'Not logged' and counts 0 hours.
B17: Leave etc. | C17: Leave, Public Holiday and Weekend days count no overhead.
B18: Overtime | C18: If Allow overtime is No, a day over its available hours is flagged in red. Extra hours show as Overtime.
B19: Weeks | C19: Weeks start on the day chosen in Settings and are cut at the month's first and last day.
B21: Legend
C22: Yellow cells with blue text are inputs - type or pick from the dropdown.
B23: 1.0 | C23: White cells are formulas - don't type over them.
B25: Example entry row (format to follow)
B26: Date | C26: Day | D26: Project Name | E26: Project Number | F26: Oracle Code | G26: Task Description | H26: System | I26: Hours
B27: 46027 | C27: Mon | D27: Project A | E27: PRJ-2041 | F27: 4100.22.07 | G27: Reviewed piping layout drawings | H27: NTIME | I27: 4

Sheet 2026 Dashboard
B1: 2026 Dashboard
B2: Year totals from the month sheets. Nothing to enter here.
B3: YEAR SUMMARY
B4: Total hours | C4: =IF(OHSystem="NTIME","NTIME (incl. overhead)","NTIME") -> NTIME | D4: =IF(OHSystem="P6","P6 (incl. overhead)","P6") -> P6 | E4: Overhead | F4: Overtime | G4: Utilisation | H4: Days logged | I4: Days not logged
B5: =G21 -> 0 | C5: =C21 -> 0 | D5: =D21 -> 0 | E5: =E21 -> 0 | F5: =F21 -> 0 | G5: =H21 -> - | H5: =I21 -> 0 | I5: =J21 -> 207
B7: MONTHLY SUMMARY
B8: Month | C8: NTIME | D8: P6 | E8: Overhead | F8: Overtime | G8: Total | H8: Utilisation | I8: Days logged | J8: Days not logged | L8: NTIME | M8: P6 | N8: Overhead
B9: January | C9: =January!M5 -> 0 | D9: =January!N5 -> 0 | E9: =January!O5 -> 0 | F9: =January!P5 -> 0 | G9: =January!L5 -> 0 | H9: =January!Q5 -> - | I9: =January!R5 -> 0 | J9: =January!S5 -> 22 | L9: =January!AF16 -> 0 | M9: =January!AG16 -> 0 | N9: =January!AH16 -> 0
B10: February | C10: =February!M5 -> 0 | D10: =February!N5 -> 0 | E10: =February!O5 -> 0 | F10: =February!P5 -> 0 | G10: =February!L5 -> 0 | H10: =February!Q5 -> - | I10: =February!R5 -> 0 | J10: =February!S5 -> 20 | L10: =February!AF16 -> 0 | M10: =February!AG16 -> 0 | N10: =February!AH16 -> 0
B11: March | C11: =March!M5 -> 0 | D11: =March!N5 -> 0 | E11: =March!O5 -> 0 | F11: =March!P5 -> 0 | G11: =March!L5 -> 0 | H11: =March!Q5 -> - | I11: =March!R5 -> 0 | J11: =March!S5 -> 22 | L11: =March!AF16 -> 0 | M11: =March!AG16 -> 0 | N11: =March!AH16 -> 0
B12: April | C12: =April!M5 -> 0 | D12: =April!N5 -> 0 | E12: =April!O5 -> 0 | F12: =April!P5 -> 0 | G12: =April!L5 -> 0 | H12: =April!Q5 -> - | I12: =April!R5 -> 0 | J12: =April!S5 -> 22 | L12: =April!AF16 -> 0 | M12: =April!AG16 -> 0 | N12: =April!AH16 -> 0
B13: May | C13: =May!M5 -> 0 | D13: =May!N5 -> 0 | E13: =May!O5 -> 0 | F13: =May!P5 -> 0 | G13: =May!L5 -> 0 | H13: =May!Q5 -> - | I13: =May!R5 -> 0 | J13: =May!S5 -> 21 | L13: =May!AF16 -> 0 | M13: =May!AG16 -> 0 | N13: =May!AH16 -> 0
B14: June | C14: =June!M5 -> 0 | D14: =June!N5 -> 0 | E14: =June!O5 -> 0 | F14: =June!P5 -> 0 | G14: =June!L5 -> 0 | H14: =June!Q5 -> - | I14: =June!R5 -> 0 | J14: =June!S5 -> 22 | L14: =June!AF16 -> 0 | M14: =June!AG16 -> 0 | N14: =June!AH16 -> 0
B15: July | C15: =July!M5 -> 0 | D15: =July!N5 -> 0 | E15: =July!O5 -> 0 | F15: =July!P5 -> 0 | G15: =July!L5 -> 0 | H15: =July!Q5 -> - | I15: =July!R5 -> 0 | J15: =July!S5 -> 23 | L15: =July!AF16 -> 0 | M15: =July!AG16 -> 0 | N15: =July!AH16 -> 0
B16: August | C16: =August!M5 -> 0 | D16: =August!N5 -> 0 | E16: =August!O5 -> 0 | F16: =August!P5 -> 0 | G16: =August!L5 -> 0 | H16: =August!Q5 -> - | I16: =August!R5 -> 0 | J16: =August!S5 -> 21 | L16: =August!AF16 -> 0 | M16: =August!AG16 -> 0 | N16: =August!AH16 -> 0
B17: September | C17: =September!M5 -> 0 | D17: =September!N5 -> 0 | E17: =September!O5 -> 0 | F17: =September!P5 -> 0 | G17: =September!L5 -> 0 | H17: =September!Q5 -> - | I17: =September!R5 -> 0 | J17: =September!S5 -> 22 | L17: =September!AF16 -> 0 | M17: =September!AG16 -> 0 | N17: =September!AH16 -> 0
B18: October | C18: =October!M5 -> 0 | D18: =October!N5 -> 0 | E18: =October!O5 -> 0 | F18: =October!P5 -> 0 | G18: =October!L5 -> 0 | H18: =October!Q5 -> - | I18: =October!R5 -> 0 | J18: =October!S5 -> 12 | L18: =October!AF16 -> 0 | M18: =October!AG16 -> 0 | N18: =October!AH16 -> 0
B19: November | C19: =November!M5 -> 0 | D19: =November!N5 -> 0 | E19: =November!O5 -> 0 | F19: =November!P5 -> 0 | G19: =November!L5 -> 0 | H19: =November!Q5 -> - | I19: =November!R5 -> 0 | J19: =November!S5 -> 0 | L19: =November!AF16 -> 0 | M19: =November!AG16 -> 0 | N19: =November!AH16 -> 0
B20: December | C20: =December!M5 -> 0 | D20: =December!N5 -> 0 | E20: =December!O5 -> 0 | F20: =December!P5 -> 0 | G20: =December!L5 -> 0 | H20: =December!Q5 -> - | I20: =December!R5 -> 0 | J20: =December!S5 -> 0 | L20: =December!AF16 -> 0 | M20: =December!AG16 -> 0 | N20: =December!AH16 -> 0
B21: Year total | C21: =SUM(C9:C20) -> 0 | D21: =SUM(D9:D20) -> 0 | E21: =SUM(E9:E20) -> 0 | F21: =SUM(F9:F20) -> 0 | G21: =SUM(G9:G20) -> 0 | H21: =IF(G21=0,"-",(SUM(L9:L20)+SUM(M9:M20))/G21) -> - | I21: =SUM(I9:I20) -> 0 | J21: =SUM(J9:J20) -> 207
B41: TOP PROJECTS 2026
B42: Project | C42: Project Number | D42: Oracle Code | E42: NTIME | F42: P6 | G42: Total | H42: % of year
B43: =IF($P43=0,"",INDEX(Projects!$B$5:$B$204,$P43)) | C43: =IF($P43=0,"",INDEX(Projects!$C$5:$C$204,$P43)) | D43: =IF($P43=0,"",INDEX(Projects!$D$5:$D$204,$P43)) | E43: =IF($P43=0,"",INDEX(Projects!$E$5:$E$204,$P43)) | F43: =IF($P43=0,"",INDEX(Projects!$F$5:$F$204,$P43)) | G43: =IF($P43=0,"",INDEX(Projects!$G$5:$G$204,$P43)) | H43: =IF(OR($P43=0,$G$21=0),"",G43/$G$21) | P43: =IF(LARGE(Projects!$I$5:$I$204,1)<=0,0,MATCH(LARGE(Projects!$I$5:$I$204,1),Projects!$I$5:$I$204,0)) -> 0
B44: =IF($P44=0,"",INDEX(Projects!$B$5:$B$204,$P44)) | C44: =IF($P44=0,"",INDEX(Projects!$C$5:$C$204,$P44)) | D44: =IF($P44=0,"",INDEX(Projects!$D$5:$D$204,$P44)) | E44: =IF($P44=0,"",INDEX(Projects!$E$5:$E$204,$P44)) | F44: =IF($P44=0,"",INDEX(Projects!$F$5:$F$204,$P44)) | G44: =IF($P44=0,"",INDEX(Projects!$G$5:$G$204,$P44)) | H44: =IF(OR($P44=0,$G$21=0),"",G44/$G$21) | P44: =IF(LARGE(Projects!$I$5:$I$204,2)<=0,0,MATCH(LARGE(Projects!$I$5:$I$204,2),Projects!$I$5:$I$204,0)) -> 0
B45: =IF($P45=0,"",INDEX(Projects!$B$5:$B$204,$P45)) | C45: =IF($P45=0,"",INDEX(Projects!$C$5:$C$204,$P45)) | D45: =IF($P45=0,"",INDEX(Projects!$D$5:$D$204,$P45)) | E45: =IF($P45=0,"",INDEX(Projects!$E$5:$E$204,$P45)) | F45: =IF($P45=0,"",INDEX(Projects!$F$5:$F$204,$P45)) | G45: =IF($P45=0,"",INDEX(Projects!$G$5:$G$204,$P45)) | H45: =IF(OR($P45=0,$G$21=0),"",G45/$G$21) | P45: =IF(LARGE(Projects!$I$5:$I$204,3)<=0,0,MATCH(LARGE(Projects!$I$5:$I$204,3),Projects!$I$5:$I$204,0)) -> 0
B46: =IF($P46=0,"",INDEX(Projects!$B$5:$B$204,$P46)) | C46: =IF($P46=0,"",INDEX(Projects!$C$5:$C$204,$P46)) | D46: =IF($P46=0,"",INDEX(Projects!$D$5:$D$204,$P46)) | E46: =IF($P46=0,"",INDEX(Projects!$E$5:$E$204,$P46)) | F46: =IF($P46=0,"",INDEX(Projects!$F$5:$F$204,$P46)) | G46: =IF($P46=0,"",INDEX(Projects!$G$5:$G$204,$P46)) | H46: =IF(OR($P46=0,$G$21=0),"",G46/$G$21) | P46: =IF(LARGE(Projects!$I$5:$I$204,4)<=0,0,MATCH(LARGE(Projects!$I$5:$I$204,4),Projects!$I$5:$I$204,0)) -> 0
B47: =IF($P47=0,"",INDEX(Projects!$B$5:$B$204,$P47)) | C47: =IF($P47=0,"",INDEX(Projects!$C$5:$C$204,$P47)) | D47: =IF($P47=0,"",INDEX(Projects!$D$5:$D$204,$P47)) | E47: =IF($P47=0,"",INDEX(Projects!$E$5:$E$204,$P47)) | F47: =IF($P47=0,"",INDEX(Projects!$F$5:$F$204,$P47)) | G47: =IF($P47=0,"",INDEX(Projects!$G$5:$G$204,$P47)) | H47: =IF(OR($P47=0,$G$21=0),"",G47/$G$21) | P47: =IF(LARGE(Projects!$I$5:$I$204,5)<=0,0,MATCH(LARGE(Projects!$I$5:$I$204,5),Projects!$I$5:$I$204,0)) -> 0
B48: =IF($P48=0,"",INDEX(Projects!$B$5:$B$204,$P48)) | C48: =IF($P48=0,"",INDEX(Projects!$C$5:$C$204,$P48)) | D48: =IF($P48=0,"",INDEX(Projects!$D$5:$D$204,$P48)) | E48: =IF($P48=0,"",INDEX(Projects!$E$5:$E$204,$P48)) | F48: =IF($P48=0,"",INDEX(Projects!$F$5:$F$204,$P48)) | G48: =IF($P48=0,"",INDEX(Projects!$G$5:$G$204,$P48)) | H48: =IF(OR($P48=0,$G$21=0),"",G48/$G$21) | P48: =IF(LARGE(Projects!$I$5:$I$204,6)<=0,0,MATCH(LARGE(Projects!$I$5:$I$204,6),Projects!$I$5:$I$204,0)) -> 0
B49: =IF($P49=0,"",INDEX(Projects!$B$5:$B$204,$P49)) | C49: =IF($P49=0,"",INDEX(Projects!$C$5:$C$204,$P49)) | D49: =IF($P49=0,"",INDEX(Projects!$D$5:$D$204,$P49)) | E49: =IF($P49=0,"",INDEX(Projects!$E$5:$E$204,$P49)) | F49: =IF($P49=0,"",INDEX(Projects!$F$5:$F$204,$P49)) | G49: =IF($P49=0,"",INDEX(Projects!$G$5:$G$204,$P49)) | H49: =IF(OR($P49=0,$G$21=0),"",G49/$G$21) | P49: =IF(LARGE(Projects!$I$5:$I$204,7)<=0,0,MATCH(LARGE(Projects!$I$5:$I$204,7),Projects!$I$5:$I$204,0)) -> 0
B50: =IF($P50=0,"",INDEX(Projects!$B$5:$B$204,$P50)) | C50: =IF($P50=0,"",INDEX(Projects!$C$5:$C$204,$P50)) | D50: =IF($P50=0,"",INDEX(Projects!$D$5:$D$204,$P50)) | E50: =IF($P50=0,"",INDEX(Projects!$E$5:$E$204,$P50)) | F50: =IF($P50=0,"",INDEX(Projects!$F$5:$F$204,$P50)) | G50: =IF($P50=0,"",INDEX(Projects!$G$5:$G$204,$P50)) | H50: =IF(OR($P50=0,$G$21=0),"",G50/$G$21) | P50: =IF(LARGE(Projects!$I$5:$I$204,8)<=0,0,MATCH(LARGE(Projects!$I$5:$I$204,8),Projects!$I$5:$I$204,0)) -> 0
B51: =IF($P51=0,"",INDEX(Projects!$B$5:$B$204,$P51)) | C51: =IF($P51=0,"",INDEX(Projects!$C$5:$C$204,$P51)) | D51: =IF($P51=0,"",INDEX(Projects!$D$5:$D$204,$P51)) | E51: =IF($P51=0,"",INDEX(Projects!$E$5:$E$204,$P51)) | F51: =IF($P51=0,"",INDEX(Projects!$F$5:$F$204,$P51)) | G51: =IF($P51=0,"",INDEX(Projects!$G$5:$G$204,$P51)) | H51: =IF(OR($P51=0,$G$21=0),"",G51/$G$21) | P51: =IF(LARGE(Projects!$I$5:$I$204,9)<=0,0,MATCH(LARGE(Projects!$I$5:$I$204,9),Projects!$I$5:$I$204,0)) -> 0
B52: =IF($P52=0,"",INDEX(Projects!$B$5:$B$204,$P52)) | C52: =IF($P52=0,"",INDEX(Projects!$C$5:$C$204,$P52)) | D52: =IF($P52=0,"",INDEX(Projects!$D$5:$D$204,$P52)) | E52: =IF($P52=0,"",INDEX(Projects!$E$5:$E$204,$P52)) | F52: =IF($P52=0,"",INDEX(Projects!$F$5:$F$204,$P52)) | G52: =IF($P52=0,"",INDEX(Projects!$G$5:$G$204,$P52)) | H52: =IF(OR($P52=0,$G$21=0),"",G52/$G$21) | P52: =IF(LARGE(Projects!$I$5:$I$204,10)<=0,0,MATCH(LARGE(Projects!$I$5:$I$204,10),Projects!$I$5:$I$204,0)) -> 0
B53: =IF($P53=0,"",INDEX(Projects!$B$5:$B$204,$P53)) | C53: =IF($P53=0,"",INDEX(Projects!$C$5:$C$204,$P53)) | D53: =IF($P53=0,"",INDEX(Projects!$D$5:$D$204,$P53)) | E53: =IF($P53=0,"",INDEX(Projects!$E$5:$E$204,$P53)) | F53: =IF($P53=0,"",INDEX(Projects!$F$5:$F$204,$P53)) | G53: =IF($P53=0,"",INDEX(Projects!$G$5:$G$204,$P53)) | H53: =IF(OR($P53=0,$G$21=0),"",G53/$G$21) | P53: =IF(LARGE(Projects!$I$5:$I$204,11)<=0,0,MATCH(LARGE(Projects!$I$5:$I$204,11),Projects!$I$5:$I$204,0)) -> 0
B54: =IF($P54=0,"",INDEX(Projects!$B$5:$B$204,$P54)) | C54: =IF($P54=0,"",INDEX(Projects!$C$5:$C$204,$P54)) | D54: =IF($P54=0,"",INDEX(Projects!$D$5:$D$204,$P54)) | E54: =IF($P54=0,"",INDEX(Projects!$E$5:$E$204,$P54)) | F54: =IF($P54=0,"",INDEX(Projects!$F$5:$F$204,$P54)) | G54: =IF($P54=0,"",INDEX(Projects!$G$5:$G$204,$P54)) | H54: =IF(OR($P54=0,$G$21=0),"",G54/$G$21) | P54: =IF(LARGE(Projects!$I$5:$I$204,12)<=0,0,MATCH(LARGE(Projects!$I$5:$I$204,12),Projects!$I$5:$I$204,0)) -> 0
B55: =IF($P55=0,"",INDEX(Projects!$B$5:$B$204,$P55)) | C55: =IF($P55=0,"",INDEX(Projects!$C$5:$C$204,$P55)) | D55: =IF($P55=0,"",INDEX(Projects!$D$5:$D$204,$P55)) | E55: =IF($P55=0,"",INDEX(Projects!$E$5:$E$204,$P55)) | F55: =IF($P55=0,"",INDEX(Projects!$F$5:$F$204,$P55)) | G55: =IF($P55=0,"",INDEX(Projects!$G$5:$G$204,$P55)) | H55: =IF(OR($P55=0,$G$21=0),"",G55/$G$21) | P55: =IF(LARGE(Projects!$I$5:$I$204,13)<=0,0,MATCH(LARGE(Projects!$I$5:$I$204,13),Projects!$I$5:$I$204,0)) -> 0
B56: =IF($P56=0,"",INDEX(Projects!$B$5:$B$204,$P56)) | C56: =IF($P56=0,"",INDEX(Projects!$C$5:$C$204,$P56)) | D56: =IF($P56=0,"",INDEX(Projects!$D$5:$D$204,$P56)) | E56: =IF($P56=0,"",INDEX(Projects!$E$5:$E$204,$P56)) | F56: =IF($P56=0,"",INDEX(Projects!$F$5:$F$204,$P56)) | G56: =IF($P56=0,"",INDEX(Projects!$G$5:$G$204,$P56)) | H56: =IF(OR($P56=0,$G$21=0),"",G56/$G$21) | P56: =IF(LARGE(Projects!$I$5:$I$204,14)<=0,0,MATCH(LARGE(Projects!$I$5:$I$204,14),Projects!$I$5:$I$204,0)) -> 0
B57: =IF($P57=0,"",INDEX(Projects!$B$5:$B$204,$P57)) | C57: =IF($P57=0,"",INDEX(Projects!$C$5:$C$204,$P57)) | D57: =IF($P57=0,"",INDEX(Projects!$D$5:$D$204,$P57)) | E57: =IF($P57=0,"",INDEX(Projects!$E$5:$E$204,$P57)) | F57: =IF($P57=0,"",INDEX(Projects!$F$5:$F$204,$P57)) | G57: =IF($P57=0,"",INDEX(Projects!$G$5:$G$204,$P57)) | H57: =IF(OR($P57=0,$G$21=0),"",G57/$G$21) | P57: =IF(LARGE(Projects!$I$5:$I$204,15)<=0,0,MATCH(LARGE(Projects!$I$5:$I$204,15),Projects!$I$5:$I$204,0)) -> 0
B58: =IF($P58=0,"",INDEX(Projects!$B$5:$B$204,$P58)) | C58: =IF($P58=0,"",INDEX(Projects!$C$5:$C$204,$P58)) | D58: =IF($P58=0,"",INDEX(Projects!$D$5:$D$204,$P58)) | E58: =IF($P58=0,"",INDEX(Projects!$E$5:$E$204,$P58)) | F58: =IF($P58=0,"",INDEX(Projects!$F$5:$F$204,$P58)) | G58: =IF($P58=0,"",INDEX(Projects!$G$5:$G$204,$P58)) | H58: =IF(OR($P58=0,$G$21=0),"",G58/$G$21) | P58: =IF(LARGE(Projects!$I$5:$I$204,16)<=0,0,MATCH(LARGE(Projects!$I$5:$I$204,16),Projects!$I$5:$I$204,0)) -> 0
B59: =IF($P59=0,"",INDEX(Projects!$B$5:$B$204,$P59)) | C59: =IF($P59=0,"",INDEX(Projects!$C$5:$C$204,$P59)) | D59: =IF($P59=0,"",INDEX(Projects!$D$5:$D$204,$P59)) | E59: =IF($P59=0,"",INDEX(Projects!$E$5:$E$204,$P59)) | F59: =IF($P59=0,"",INDEX(Projects!$F$5:$F$204,$P59)) | G59: =IF($P59=0,"",INDEX(Projects!$G$5:$G$204,$P59)) | H59: =IF(OR($P59=0,$G$21=0),"",G59/$G$21) | P59: =IF(LARGE(Projects!$I$5:$I$204,17)<=0,0,MATCH(LARGE(Projects!$I$5:$I$204,17),Projects!$I$5:$I$204,0)) -> 0
B60: =IF($P60=0,"",INDEX(Projects!$B$5:$B$204,$P60)) | C60: =IF($P60=0,"",INDEX(Projects!$C$5:$C$204,$P60)) | D60: =IF($P60=0,"",INDEX(Projects!$D$5:$D$204,$P60)) | E60: =IF($P60=0,"",INDEX(Projects!$E$5:$E$204,$P60)) | F60: =IF($P60=0,"",INDEX(Projects!$F$5:$F$204,$P60)) | G60: =IF($P60=0,"",INDEX(Projects!$G$5:$G$204,$P60)) | H60: =IF(OR($P60=0,$G$21=0),"",G60/$G$21) | P60: =IF(LARGE(Projects!$I$5:$I$204,18)<=0,0,MATCH(LARGE(Projects!$I$5:$I$204,18),Projects!$I$5:$I$204,0)) -> 0
...

Sheet January
B1: January 2026 | AC1: Helpers
B2: Add one row per task in the Entry log. Everything on the right updates automatically. | AC2: 46023
B3: ENTRY LOG | L3: MONTH SUMMARY | AC3: 46053
L4: Total hours | M4: =IF(OHSystem="NTIME","NTIME (incl. overhead)","NTIME") -> NTIME | N4: =IF(OHSystem="P6","P6 (incl. overhead)","P6") -> P6 | O4: Overhead | P4: Overtime | Q4: Utilisation | R4: Days logged | S4: Days not logged | AC4: =AC2-MOD(WEEKDAY(AC2,2)-WeekStartNum,7) -> 46020
L5: =SUM($T$58:$T$88) -> 0 | M5: =SUM($P$58:$P$88)+IF(OHSystem="NTIME",SUM($R$58:$R$88),0) -> 0 | N5: =SUM($Q$58:$Q$88)+IF(OHSystem="P6",SUM($R$58:$R$88),0) -> 0 | O5: =SUM($R$58:$R$88) -> 0 | P5: =SUM($S$58:$S$88) -> 0 | Q5: =IF(L5=0,"-",(SUM($P$58:$P$88)+SUM($Q$58:$Q$88))/L5) -> - | R5: =SUMPRODUCT(($N$58:$N$88="Working")*(($P$58:$P$88+$Q$58:$Q$88)>0))+COUNTIF($N$58:$N$88,"Overhead only") -> 0 | S5: =COUNTIF($U$58:$U$88,"Not logged") -> 22
B6: Date | C6: Day | D6: Project Name | E6: Project Number | F6: Oracle Code | G6: Task Description | H6: System | I6: Hours | J6: Check
C7: =IF(B7="","",TEXT(B7,"ddd")) | E7: =IF(D7="","",IFERROR(INDEX(ProjNumbers,MATCH(D7,ProjNames,0)),"")) | F7: =IF(D7="","",IFERROR(INDEX(ProjCodes,MATCH(D7,ProjNames,0)),"")) | J7: =IF(COUNTA(B7,D7,G7,H7,I7)=0,"",IF(B7="","Enter date",IF(OR(B7<$AC$2,B7>$AC$3),"Date not in January",IF(D7="","Pick project",IF(ISNA(MATCH(D7,ProjNames,0)),"Project not in list",IF(G7="","Add task description",IF(H7="","Pick NTIME or P6",IF(N(I7)<=0,"Enter hours",IF(AND(AllowOT<>"Yes",SUMIF($B$7:$B$256,B7,$I$7:$I$256)>INDEX($O$58:$O$88,DAY(B7))),"Day over "&INDEX($O$58:$O$88,DAY(B7))&" h","✓"))))))))) | W7: =IF(Projects!B5="","",Projects!B5) -> Project A | X7: =IF(W7="",0,SUMIFS($I$7:$I$256,$D$7:$D$256,W7,$H$7:$H$256,"NTIME")) -> 0 | Y7: =IF(W7="",0,SUMIFS($I$7:$I$256,$D$7:$D$256,W7,$H$7:$H$256,"P6")) -> 0 | Z7: =X7+Y7 -> 0 | AA7: =IF(Z7>0,Z7+(201-1)/10^6,0) -> 0
C8: =IF(B8="","",TEXT(B8,"ddd")) | E8: =IF(D8="","",IFERROR(INDEX(ProjNumbers,MATCH(D8,ProjNames,0)),"")) | F8: =IF(D8="","",IFERROR(INDEX(ProjCodes,MATCH(D8,ProjNames,0)),"")) | J8: =IF(COUNTA(B8,D8,G8,H8,I8)=0,"",IF(B8="","Enter date",IF(OR(B8<$AC$2,B8>$AC$3),"Date not in January",IF(D8="","Pick project",IF(ISNA(MATCH(D8,ProjNames,0)),"Project not in list",IF(G8="","Add task description",IF(H8="","Pick NTIME or P6",IF(N(I8)<=0,"Enter hours",IF(AND(AllowOT<>"Yes",SUMIF($B$7:$B$256,B8,$I$7:$I$256)>INDEX($O$58:$O$88,DAY(B8))),"Day over "&INDEX($O$58:$O$88,DAY(B8))&" h","✓"))))))))) | L8: WEEKLY SUMMARY | W8: =IF(Projects!B6="","",Projects!B6) | X8: =IF(W8="",0,SUMIFS($I$7:$I$256,$D$7:$D$256,W8,$H$7:$H$256,"NTIME")) -> 0 | Y8: =IF(W8="",0,SUMIFS($I$7:$I$256,$D$7:$D$256,W8,$H$7:$H$256,"P6")) -> 0 | Z8: =X8+Y8 -> 0 | AA8: =IF(Z8>0,Z8+(201-2)/10^6,0) -> 0
C9: =IF(B9="","",TEXT(B9,"ddd")) | E9: =IF(D9="","",IFERROR(INDEX(ProjNumbers,MATCH(D9,ProjNames,0)),"")) | F9: =IF(D9="","",IFERROR(INDEX(ProjCodes,MATCH(D9,ProjNames,0)),"")) | J9: =IF(COUNTA(B9,D9,G9,H9,I9)=0,"",IF(B9="","Enter date",IF(OR(B9<$AC$2,B9>$AC$3),"Date not in January",IF(D9="","Pick project",IF(ISNA(MATCH(D9,ProjNames,0)),"Project not in list",IF(G9="","Add task description",IF(H9="","Pick NTIME or P6",IF(N(I9)<=0,"Enter hours",IF(AND(AllowOT<>"Yes",SUMIF($B$7:$B$256,B9,$I$7:$I$256)>INDEX($O$58:$O$88,DAY(B9))),"Day over "&INDEX($O$58:$O$88,DAY(B9))&" h","✓"))))))))) | L9: Week | M9: From | N9: To | O9: NTIME | P9: P6 | Q9: Overhead | R9: Overtime | S9: Total | W9: =IF(Projects!B7="","",Projects!B7) | X9: =IF(W9="",0,SUMIFS($I$7:$I$256,$D$7:$D$256,W9,$H$7:$H$256,"NTIME")) -> 0 | Y9: =IF(W9="",0,SUMIFS($I$7:$I$256,$D$7:$D$256,W9,$H$7:$H$256,"P6")) -> 0 | Z9: =X9+Y9 -> 0 | AA9: =IF(Z9>0,Z9+(201-3)/10^6,0) -> 0 | AF9: NTIME | AG9: P6 | AH9: Overhead
C10: =IF(B10="","",TEXT(B10,"ddd")) | E10: =IF(D10="","",IFERROR(INDEX(ProjNumbers,MATCH(D10,ProjNames,0)),"")) | F10: =IF(D10="","",IFERROR(INDEX(ProjCodes,MATCH(D10,ProjNames,0)),"")) | J10: =IF(COUNTA(B10,D10,G10,H10,I10)=0,"",IF(B10="","Enter date",IF(OR(B10<$AC$2,B10>$AC$3),"Date not in January",IF(D10="","Pick project",IF(ISNA(MATCH(D10,ProjNames,0)),"Project not in list",IF(G10="","Add task description",IF(H10="","Pick NTIME or P6",IF(N(I10)<=0,"Enter hours",IF(AND(AllowOT<>"Yes",SUMIF($B$7:$B$256,B10,$I$7:$I$256)>INDEX($O$58:$O$88,DAY(B10))),"Day over "&INDEX($O$58:$O$88,DAY(B10))&" h","✓"))))))))) | L10: ="Week 1"&IF(M10="",""," ("&DAY(M10)&"–"&DAY(N10)&")") -> Week 1 (1–4) | M10: =IF($AC$4+7*0>$AC$3,"",MAX($AC$2,$AC$4+7*0)) -> 46023 | N10: =IF(M10="","",MIN($AC$3,$AC$4+7*1-1)) -> 46026 | O10: =IF($M10="","",AF10+IF(OHSystem="NTIME",AH10,0)) -> 0 | P10: =IF($M10="","",AG10+IF(OHSystem="P6",AH10,0)) -> 0 | Q10: =IF($M10="","",AH10) -> 0 | R10: =IF($M10="","",SUMIFS($S$58:$S$88,$L$58:$L$88,">="&$M10,$L$58:$L$88,"<="&$N10)) -> 0 | S10: =IF($M10="","",SUMIFS($T$58:$T$88,$L$58:$L$88,">="&$M10,$L$58:$L$88,"<="&$N10)) -> 0 | W10: =IF(Projects!B8="","",Projects!B8) | X10: =IF(W10="",0,SUMIFS($I$7:$I$256,$D$7:$D$256,W10,$H$7:$H$256,"NTIME")) -> 0 | Y10: =IF(W10="",0,SUMIFS($I$7:$I$256,$D$7:$D$256,W10,$H$7:$H$256,"P6")) -> 0 | Z10: =X10+Y10 -> 0 | AA10: =IF(Z10>0,Z10+(201-4)/10^6,0) -> 0 | AF10: =IF($M10="",0,SUMIFS($P$58:$P$88,$L$58:$L$88,">="&$M10,$L$58:$L$88,"<="&$N10)) -> 0 | AG10: =IF($M10="",0,SUMIFS($Q$58:$Q$88,$L$58:$L$88,">="&$M10,$L$58:$L$88,"<="&$N10)) -> 0 | AH10: =IF($M10="",0,SUMIFS($R$58:$R$88,$L$58:$L$88,">="&$M10,$L$58:$L$88,"<="&$N10)) -> 0
C11: =IF(B11="","",TEXT(B11,"ddd")) | E11: =IF(D11="","",IFERROR(INDEX(ProjNumbers,MATCH(D11,ProjNames,0)),"")) | F11: =IF(D11="","",IFERROR(INDEX(ProjCodes,MATCH(D11,ProjNames,0)),"")) | J11: =IF(COUNTA(B11,D11,G11,H11,I11)=0,"",IF(B11="","Enter date",IF(OR(B11<$AC$2,B11>$AC$3),"Date not in January",IF(D11="","Pick project",IF(ISNA(MATCH(D11,ProjNames,0)),"Project not in list",IF(G11="","Add task description",IF(H11="","Pick NTIME or P6",IF(N(I11)<=0,"Enter hours",IF(AND(AllowOT<>"Yes",SUMIF($B$7:$B$256,B11,$I$7:$I$256)>INDEX($O$58:$O$88,DAY(B11))),"Day over "&INDEX($O$58:$O$88,DAY(B11))&" h","✓"))))))))) | L11: ="Week 2"&IF(M11="",""," ("&DAY(M11)&"–"&DAY(N11)&")") -> Week 2 (5–11) | M11: =IF($AC$4+7*1>$AC$3,"",MAX($AC$2,$AC$4+7*1)) -> 46027 | N11: =IF(M11="","",MIN($AC$3,$AC$4+7*2-1)) -> 46033 | O11: =IF($M11="","",AF11+IF(OHSystem="NTIME",AH11,0)) -> 0 | P11: =IF($M11="","",AG11+IF(OHSystem="P6",AH11,0)) -> 0 | Q11: =IF($M11="","",AH11) -> 0 | R11: =IF($M11="","",SUMIFS($S$58:$S$88,$L$58:$L$88,">="&$M11,$L$58:$L$88,"<="&$N11)) -> 0 | S11: =IF($M11="","",SUMIFS($T$58:$T$88,$L$58:$L$88,">="&$M11,$L$58:$L$88,"<="&$N11)) -> 0 | W11: =IF(Projects!B9="","",Projects!B9) | X11: =IF(W11="",0,SUMIFS($I$7:$I$256,$D$7:$D$256,W11,$H$7:$H$256,"NTIME")) -> 0 | Y11: =IF(W11="",0,SUMIFS($I$7:$I$256,$D$7:$D$256,W11,$H$7:$H$256,"P6")) -> 0 | Z11: =X11+Y11 -> 0 | AA11: =IF(Z11>0,Z11+(201-5)/10^6,0) -> 0 | AF11: =IF($M11="",0,SUMIFS($P$58:$P$88,$L$58:$L$88,">="&$M11,$L$58:$L$88,"<="&$N11)) -> 0 | AG11: =IF($M11="",0,SUMIFS($Q$58:$Q$88,$L$58:$L$88,">="&$M11,$L$58:$L$88,"<="&$N11)) -> 0 | AH11: =IF($M11="",0,SUMIFS($R$58:$R$88,$L$58:$L$88,">="&$M11,$L$58:$L$88,"<="&$N11)) -> 0
C12: =IF(B12="","",TEXT(B12,"ddd")) | E12: =IF(D12="","",IFERROR(INDEX(ProjNumbers,MATCH(D12,ProjNames,0)),"")) | F12: =IF(D12="","",IFERROR(INDEX(ProjCodes,MATCH(D12,ProjNames,0)),"")) | J12: =IF(COUNTA(B12,D12,G12,H12,I12)=0,"",IF(B12="","Enter date",IF(OR(B12<$AC$2,B12>$AC$3),"Date not in January",IF(D12="","Pick project",IF(ISNA(MATCH(D12,ProjNames,0)),"Project not in list",IF(G12="","Add task description",IF(H12="","Pick NTIME or P6",IF(N(I12)<=0,"Enter hours",IF(AND(AllowOT<>"Yes",SUMIF($B$7:$B$256,B12,$I$7:$I$256)>INDEX($O$58:$O$88,DAY(B12))),"Day over "&INDEX($O$58:$O$88,DAY(B12))&" h","✓"))))))))) | L12: ="Week 3"&IF(M12="",""," ("&DAY(M12)&"–"&DAY(N12)&")") -> Week 3 (12–18) | M12: =IF($AC$4+7*2>$AC$3,"",MAX($AC$2,$AC$4+7*2)) -> 46034 | N12: =IF(M12="","",MIN($AC$3,$AC$4+7*3-1)) -> 46040 | O12: =IF($M12="","",AF12+IF(OHSystem="NTIME",AH12,0)) -> 0 | P12: =IF($M12="","",AG12+IF(OHSystem="P6",AH12,0)) -> 0 | Q12: =IF($M12="","",AH12) -> 0 | R12: =IF($M12="","",SUMIFS($S$58:$S$88,$L$58:$L$88,">="&$M12,$L$58:$L$88,"<="&$N12)) -> 0 | S12: =IF($M12="","",SUMIFS($T$58:$T$88,$L$58:$L$88,">="&$M12,$L$58:$L$88,"<="&$N12)) -> 0 | W12: =IF(Projects!B10="","",Projects!B10) | X12: =IF(W12="",0,SUMIFS($I$7:$I$256,$D$7:$D$256,W12,$H$7:$H$256,"NTIME")) -> 0 | Y12: =IF(W12="",0,SUMIFS($I$7:$I$256,$D$7:$D$256,W12,$H$7:$H$256,"P6")) -> 0 | Z12: =X12+Y12 -> 0 | AA12: =IF(Z12>0,Z12+(201-6)/10^6,0) -> 0 | AF12: =IF($M12="",0,SUMIFS($P$58:$P$88,$L$58:$L$88,">="&$M12,$L$58:$L$88,"<="&$N12)) -> 0 | AG12: =IF($M12="",0,SUMIFS($Q$58:$Q$88,$L$58:$L$88,">="&$M12,$L$58:$L$88,"<="&$N12)) -> 0 | AH12: =IF($M12="",0,SUMIFS($R$58:$R$88,$L$58:$L$88,">="&$M12,$L$58:$L$88,"<="&$N12)) -> 0
C13: =IF(B13="","",TEXT(B13,"ddd")) | E13: =IF(D13="","",IFERROR(INDEX(ProjNumbers,MATCH(D13,ProjNames,0)),"")) | F13: =IF(D13="","",IFERROR(INDEX(ProjCodes,MATCH(D13,ProjNames,0)),"")) | J13: =IF(COUNTA(B13,D13,G13,H13,I13)=0,"",IF(B13="","Enter date",IF(OR(B13<$AC$2,B13>$AC$3),"Date not in January",IF(D13="","Pick project",IF(ISNA(MATCH(D13,ProjNames,0)),"Project not in list",IF(G13="","Add task description",IF(H13="","Pick NTIME or P6",IF(N(I13)<=0,"Enter hours",IF(AND(AllowOT<>"Yes",SUMIF($B$7:$B$256,B13,$I$7:$I$256)>INDEX($O$58:$O$88,DAY(B13))),"Day over "&INDEX($O$58:$O$88,DAY(B13))&" h","✓"))))))))) | L13: ="Week 4"&IF(M13="",""," ("&DAY(M13)&"–"&DAY(N13)&")") -> Week 4 (19–25) | M13: =IF($AC$4+7*3>$AC$3,"",MAX($AC$2,$AC$4+7*3)) -> 46041 | N13: =IF(M13="","",MIN($AC$3,$AC$4+7*4-1)) -> 46047 | O13: =IF($M13="","",AF13+IF(OHSystem="NTIME",AH13,0)) -> 0 | P13: =IF($M13="","",AG13+IF(OHSystem="P6",AH13,0)) -> 0 | Q13: =IF($M13="","",AH13) -> 0 | R13: =IF($M13="","",SUMIFS($S$58:$S$88,$L$58:$L$88,">="&$M13,$L$58:$L$88,"<="&$N13)) -> 0 | S13: =IF($M13="","",SUMIFS($T$58:$T$88,$L$58:$L$88,">="&$M13,$L$58:$L$88,"<="&$N13)) -> 0 | W13: =IF(Projects!B11="","",Projects!B11) | X13: =IF(W13="",0,SUMIFS($I$7:$I$256,$D$7:$D$256,W13,$H$7:$H$256,"NTIME")) -> 0 | Y13: =IF(W13="",0,SUMIFS($I$7:$I$256,$D$7:$D$256,W13,$H$7:$H$256,"P6")) -> 0 | Z13: =X13+Y13 -> 0 | AA13: =IF(Z13>0,Z13+(201-7)/10^6,0) -> 0 | AF13: =IF($M13="",0,SUMIFS($P$58:$P$88,$L$58:$L$88,">="&$M13,$L$58:$L$88,"<="&$N13)) -> 0 | AG13: =IF($M13="",0,SUMIFS($Q$58:$Q$88,$L$58:$L$88,">="&$M13,$L$58:$L$88,"<="&$N13)) -> 0 | AH13: =IF($M13="",0,SUMIFS($R$58:$R$88,$L$58:$L$88,">="&$M13,$L$58:$L$88,"<="&$N13)) -> 0
C14: =IF(B14="","",TEXT(B14,"ddd")) | E14: =IF(D14="","",IFERROR(INDEX(ProjNumbers,MATCH(D14,ProjNames,0)),"")) | F14: =IF(D14="","",IFERROR(INDEX(ProjCodes,MATCH(D14,ProjNames,0)),"")) | J14: =IF(COUNTA(B14,D14,G14,H14,I14)=0,"",IF(B14="","Enter date",IF(OR(B14<$AC$2,B14>$AC$3),"Date not in January",IF(D14="","Pick project",IF(ISNA(MATCH(D14,ProjNames,0)),"Project not in list",IF(G14="","Add task description",IF(H14="","Pick NTIME or P6",IF(N(I14)<=0,"Enter hours",IF(AND(AllowOT<>"Yes",SUMIF($B$7:$B$256,B14,$I$7:$I$256)>INDEX($O$58:$O$88,DAY(B14))),"Day over "&INDEX($O$58:$O$88,DAY(B14))&" h","✓"))))))))) | L14: ="Week 5"&IF(M14="",""," ("&DAY(M14)&"–"&DAY(N14)&")") -> Week 5 (26–31) | M14: =IF($AC$4+7*4>$AC$3,"",MAX($AC$2,$AC$4+7*4)) -> 46048 | N14: =IF(M14="","",MIN($AC$3,$AC$4+7*5-1)) -> 46053 | O14: =IF($M14="","",AF14+IF(OHSystem="NTIME",AH14,0)) -> 0 | P14: =IF($M14="","",AG14+IF(OHSystem="P6",AH14,0)) -> 0 | Q14: =IF($M14="","",AH14) -> 0 | R14: =IF($M14="","",SUMIFS($S$58:$S$88,$L$58:$L$88,">="&$M14,$L$58:$L$88,"<="&$N14)) -> 0 | S14: =IF($M14="","",SUMIFS($T$58:$T$88,$L$58:$L$88,">="&$M14,$L$58:$L$88,"<="&$N14)) -> 0 | W14: =IF(Projects!B12="","",Projects!B12) | X14: =IF(W14="",0,SUMIFS($I$7:$I$256,$D$7:$D$256,W14,$H$7:$H$256,"NTIME")) -> 0 | Y14: =IF(W14="",0,SUMIFS($I$7:$I$256,$D$7:$D$256,W14,$H$7:$H$256,"P6")) -> 0 | Z14: =X14+Y14 -> 0 | AA14: =IF(Z14>0,Z14+(201-8)/10^6,0) -> 0 | AF14: =IF($M14="",0,SUMIFS($P$58:$P$88,$L$58:$L$88,">="&$M14,$L$58:$L$88,"<="&$N14)) -> 0 | AG14: =IF($M14="",0,SUMIFS($Q$58:$Q$88,$L$58:$L$88,">="&$M14,$L$58:$L$88,"<="&$N14)) -> 0 | AH14: =IF($M14="",0,SUMIFS($R$58:$R$88,$L$58:$L$88,">="&$M14,$L$58:$L$88,"<="&$N14)) -> 0
C15: =IF(B15="","",TEXT(B15,"ddd")) | E15: =IF(D15="","",IFERROR(INDEX(ProjNumbers,MATCH(D15,ProjNames,0)),"")) | F15: =IF(D15="","",IFERROR(INDEX(ProjCodes,MATCH(D15,ProjNames,0)),"")) | J15: =IF(COUNTA(B15,D15,G15,H15,I15)=0,"",IF(B15="","Enter date",IF(OR(B15<$AC$2,B15>$AC$3),"Date not in January",IF(D15="","Pick project",IF(ISNA(MATCH(D15,ProjNames,0)),"Project not in list",IF(G15="","Add task description",IF(H15="","Pick NTIME or P6",IF(N(I15)<=0,"Enter hours",IF(AND(AllowOT<>"Yes",SUMIF($B$7:$B$256,B15,$I$7:$I$256)>INDEX($O$58:$O$88,DAY(B15))),"Day over "&INDEX($O$58:$O$88,DAY(B15))&" h","✓"))))))))) | L15: ="Week 6"&IF(M15="",""," ("&DAY(M15)&"–"&DAY(N15)&")") -> Week 6 | M15: =IF($AC$4+7*5>$AC$3,"",MAX($AC$2,$AC$4+7*5)) | N15: =IF(M15="","",MIN($AC$3,$AC$4+7*6-1)) | O15: =IF($M15="","",AF15+IF(OHSystem="NTIME",AH15,0)) | P15: =IF($M15="","",AG15+IF(OHSystem="P6",AH15,0)) | Q15: =IF($M15="","",AH15) | R15: =IF($M15="","",SUMIFS($S$58:$S$88,$L$58:$L$88,">="&$M15,$L$58:$L$88,"<="&$N15)) | S15: =IF($M15="","",SUMIFS($T$58:$T$88,$L$58:$L$88,">="&$M15,$L$58:$L$88,"<="&$N15)) | W15: =IF(Projects!B13="","",Projects!B13) | X15: =IF(W15="",0,SUMIFS($I$7:$I$256,$D$7:$D$256,W15,$H$7:$H$256,"NTIME")) -> 0 | Y15: =IF(W15="",0,SUMIFS($I$7:$I$256,$D$7:$D$256,W15,$H$7:$H$256,"P6")) -> 0 | Z15: =X15+Y15 -> 0 | AA15: =IF(Z15>0,Z15+(201-9)/10^6,0) -> 0 | AF15: =IF($M15="",0,SUMIFS($P$58:$P$88,$L$58:$L$88,">="&$M15,$L$58:$L$88,"<="&$N15)) -> 0 | AG15: =IF($M15="",0,SUMIFS($Q$58:$Q$88,$L$58:$L$88,">="&$M15,$L$58:$L$88,"<="&$N15)) -> 0 | AH15: =IF($M15="",0,SUMIFS($R$58:$R$88,$L$58:$L$88,">="&$M15,$L$58:$L$88,"<="&$N15)) -> 0
C16: =IF(B16="","",TEXT(B16,"ddd")) | E16: =IF(D16="","",IFERROR(INDEX(ProjNumbers,MATCH(D16,ProjNames,0)),"")) | F16: =IF(D16="","",IFERROR(INDEX(ProjCodes,MATCH(D16,ProjNames,0)),"")) | J16: =IF(COUNTA(B16,D16,G16,H16,I16)=0,"",IF(B16="","Enter date",IF(OR(B16<$AC$2,B16>$AC$3),"Date not in January",IF(D16="","Pick project",IF(ISNA(MATCH(D16,ProjNames,0)),"Project not in list",IF(G16="","Add task description",IF(H16="","Pick NTIME or P6",IF(N(I16)<=0,"Enter hours",IF(AND(AllowOT<>"Yes",SUMIF($B$7:$B$256,B16,$I$7:$I$256)>INDEX($O$58:$O$88,DAY(B16))),"Day over "&INDEX($O$58:$O$88,DAY(B16))&" h","✓"))))))))) | L16: Month total | O16: =SUM(O10:O15) -> 0 | P16: =SUM(P10:P15) -> 0 | Q16: =SUM(Q10:Q15) -> 0 | R16: =SUM(R10:R15) -> 0 | S16: =SUM(S10:S15) -> 0 | W16: =IF(Projects!B14="","",Projects!B14) | X16: =IF(W16="",0,SUMIFS($I$7:$I$256,$D$7:$D$256,W16,$H$7:$H$256,"NTIME")) -> 0 | Y16: =IF(W16="",0,SUMIFS($I$7:$I$256,$D$7:$D$256,W16,$H$7:$H$256,"P6")) -> 0 | Z16: =X16+Y16 -> 0 | AA16: =IF(Z16>0,Z16+(201-10)/10^6,0) -> 0 | AF16: =SUM(AF10:AF15) -> 0 | AG16: =SUM(AG10:AG15) -> 0 | AH16: =SUM(AH10:AH15) -> 0
C17: =IF(B17="","",TEXT(B17,"ddd")) | E17: =IF(D17="","",IFERROR(INDEX(ProjNumbers,MATCH(D17,ProjNames,0)),"")) | F17: =IF(D17="","",IFERROR(INDEX(ProjCodes,MATCH(D17,ProjNames,0)),"")) | J17: =IF(COUNTA(B17,D17,G17,H17,I17)=0,"",IF(B17="","Enter date",IF(OR(B17<$AC$2,B17>$AC$3),"Date not in January",IF(D17="","Pick project",IF(ISNA(MATCH(D17,ProjNames,0)),"Project not in list",IF(G17="","Add task description",IF(H17="","Pick NTIME or P6",IF(N(I17)<=0,"Enter hours",IF(AND(AllowOT<>"Yes",SUMIF($B$7:$B$256,B17,$I$7:$I$256)>INDEX($O$58:$O$88,DAY(B17))),"Day over "&INDEX($O$58:$O$88,DAY(B17))&" h","✓"))))))))) | W17: =IF(Projects!B15="","",Projects!B15) | X17: =IF(W17="",0,SUMIFS($I$7:$I$256,$D$7:$D$256,W17,$H$7:$H$256,"NTIME")) -> 0 | Y17: =IF(W17="",0,SUMIFS($I$7:$I$256,$D$7:$D$256,W17,$H$7:$H$256,"P6")) -> 0 | Z17: =X17+Y17 -> 0 | AA17: =IF(Z17>0,Z17+(201-11)/10^6,0) -> 0
C18: =IF(B18="","",TEXT(B18,"ddd")) | E18: =IF(D18="","",IFERROR(INDEX(ProjNumbers,MATCH(D18,ProjNames,0)),"")) | F18: =IF(D18="","",IFERROR(INDEX(ProjCodes,MATCH(D18,ProjNames,0)),"")) | J18: =IF(COUNTA(B18,D18,G18,H18,I18)=0,"",IF(B18="","Enter date",IF(OR(B18<$AC$2,B18>$AC$3),"Date not in January",IF(D18="","Pick project",IF(ISNA(MATCH(D18,ProjNames,0)),"Project not in list",IF(G18="","Add task description",IF(H18="","Pick NTIME or P6",IF(N(I18)<=0,"Enter hours",IF(AND(AllowOT<>"Yes",SUMIF($B$7:$B$256,B18,$I$7:$I$256)>INDEX($O$58:$O$88,DAY(B18))),"Day over "&INDEX($O$58:$O$88,DAY(B18))&" h","✓"))))))))) | W18: =IF(Projects!B16="","",Projects!B16) | X18: =IF(W18="",0,SUMIFS($I$7:$I$256,$D$7:$D$256,W18,$H$7:$H$256,"NTIME")) -> 0 | Y18: =IF(W18="",0,SUMIFS($I$7:$I$256,$D$7:$D$256,W18,$H$7:$H$256,"P6")) -> 0 | Z18: =X18+Y18 -> 0 | AA18: =IF(Z18>0,Z18+(201-12)/10^6,0) -> 0
C19: =IF(B19="","",TEXT(B19,"ddd")) | E19: =IF(D19="","",IFERROR(INDEX(ProjNumbers,MATCH(D19,ProjNames,0)),"")) | F19: =IF(D19="","",IFERROR(INDEX(ProjCodes,MATCH(D19,ProjNames,0)),"")) | J19: =IF(COUNTA(B19,D19,G19,H19,I19)=0,"",IF(B19="","Enter date",IF(OR(B19<$AC$2,B19>$AC$3),"Date not in January",IF(D19="","Pick project",IF(ISNA(MATCH(D19,ProjNames,0)),"Project not in list",IF(G19="","Add task description",IF(H19="","Pick NTIME or P6",IF(N(I19)<=0,"Enter hours",IF(AND(AllowOT<>"Yes",SUMIF($B$7:$B$256,B19,$I$7:$I$256)>INDEX($O$58:$O$88,DAY(B19))),"Day over "&INDEX($O$58:$O$88,DAY(B19))&" h","✓"))))))))) | W19: =IF(Projects!B17="","",Projects!B17) | X19: =IF(W19="",0,SUMIFS($I$7:$I$256,$D$7:$D$256,W19,$H$7:$H$256,"NTIME")) -> 0 | Y19: =IF(W19="",0,SUMIFS($I$7:$I$256,$D$7:$D$256,W19,$H$7:$H$256,"P6")) -> 0 | Z19: =X19+Y19 -> 0 | AA19: =IF(Z19>0,Z19+(201-13)/10^6,0) -> 0
C20: =IF(B20="","",TEXT(B20,"ddd")) | E20: =IF(D20="","",IFERROR(INDEX(ProjNumbers,MATCH(D20,ProjNames,0)),"")) | F20: =IF(D20="","",IFERROR(INDEX(ProjCodes,MATCH(D20,ProjNames,0)),"")) | J20: =IF(COUNTA(B20,D20,G20,H20,I20)=0,"",IF(B20="","Enter date",IF(OR(B20<$AC$2,B20>$AC$3),"Date not in January",IF(D20="","Pick project",IF(ISNA(MATCH(D20,ProjNames,0)),"Project not in list",IF(G20="","Add task description",IF(H20="","Pick NTIME or P6",IF(N(I20)<=0,"Enter hours",IF(AND(AllowOT<>"Yes",SUMIF($B$7:$B$256,B20,$I$7:$I$256)>INDEX($O$58:$O$88,DAY(B20))),"Day over "&INDEX($O$58:$O$88,DAY(B20))&" h","✓"))))))))) | W20: =IF(Projects!B18="","",Projects!B18) | X20: =IF(W20="",0,SUMIFS($I$7:$I$256,$D$7:$D$256,W20,$H$7:$H$256,"NTIME")) -> 0 | Y20: =IF(W20="",0,SUMIFS($I$7:$I$256,$D$7:$D$256,W20,$H$7:$H$256,"P6")) -> 0 | Z20: =X20+Y20 -> 0 | AA20: =IF(Z20>0,Z20+(201-14)/10^6,0) -> 0
C21: =IF(B21="","",TEXT(B21,"ddd")) | E21: =IF(D21="","",IFERROR(INDEX(ProjNumbers,MATCH(D21,ProjNames,0)),"")) | F21: =IF(D21="","",IFERROR(INDEX(ProjCodes,MATCH(D21,ProjNames,0)),"")) | J21: =IF(COUNTA(B21,D21,G21,H21,I21)=0,"",IF(B21="","Enter date",IF(OR(B21<$AC$2,B21>$AC$3),"Date not in January",IF(D21="","Pick project",IF(ISNA(MATCH(D21,ProjNames,0)),"Project not in list",IF(G21="","Add task description",IF(H21="","Pick NTIME or P6",IF(N(I21)<=0,"Enter hours",IF(AND(AllowOT<>"Yes",SUMIF($B$7:$B$256,B21,$I$7:$I$256)>INDEX($O$58:$O$88,DAY(B21))),"Day over "&INDEX($O$58:$O$88,DAY(B21))&" h","✓"))))))))) | W21: =IF(Projects!B19="","",Projects!B19) | X21: =IF(W21="",0,SUMIFS($I$7:$I$256,$D$7:$D$256,W21,$H$7:$H$256,"NTIME")) -> 0 | Y21: =IF(W21="",0,SUMIFS($I$7:$I$256,$D$7:$D$256,W21,$H$7:$H$256,"P6")) -> 0 | Z21: =X21+Y21 -> 0 | AA21: =IF(Z21>0,Z21+(201-15)/10^6,0) -> 0
C22: =IF(B22="","",TEXT(B22,"ddd")) | E22: =IF(D22="","",IFERROR(INDEX(ProjNumbers,MATCH(D22,ProjNames,0)),"")) | F22: =IF(D22="","",IFERROR(INDEX(ProjCodes,MATCH(D22,ProjNames,0)),"")) | J22: =IF(COUNTA(B22,D22,G22,H22,I22)=0,"",IF(B22="","Enter date",IF(OR(B22<$AC$2,B22>$AC$3),"Date not in January",IF(D22="","Pick project",IF(ISNA(MATCH(D22,ProjNames,0)),"Project not in list",IF(G22="","Add task description",IF(H22="","Pick NTIME or P6",IF(N(I22)<=0,"Enter hours",IF(AND(AllowOT<>"Yes",SUMIF($B$7:$B$256,B22,$I$7:$I$256)>INDEX($O$58:$O$88,DAY(B22))),"Day over "&INDEX($O$58:$O$88,DAY(B22))&" h","✓"))))))))) | W22: =IF(Projects!B20="","",Projects!B20) | X22: =IF(W22="",0,SUMIFS($I$7:$I$256,$D$7:$D$256,W22,$H$7:$H$256,"NTIME")) -> 0 | Y22: =IF(W22="",0,SUMIFS($I$7:$I$256,$D$7:$D$256,W22,$H$7:$H$256,"P6")) -> 0 | Z22: =X22+Y22 -> 0 | AA22: =IF(Z22>0,Z22+(201-16)/10^6,0) -> 0
C23: =IF(B23="","",TEXT(B23,"ddd")) | E23: =IF(D23="","",IFERROR(INDEX(ProjNumbers,MATCH(D23,ProjNames,0)),"")) | F23: =IF(D23="","",IFERROR(INDEX(ProjCodes,MATCH(D23,ProjNames,0)),"")) | J23: =IF(COUNTA(B23,D23,G23,H23,I23)=0,"",IF(B23="","Enter date",IF(OR(B23<$AC$2,B23>$AC$3),"Date not in January",IF(D23="","Pick project",IF(ISNA(MATCH(D23,ProjNames,0)),"Project not in list",IF(G23="","Add task description",IF(H23="","Pick NTIME or P6",IF(N(I23)<=0,"Enter hours",IF(AND(AllowOT<>"Yes",SUMIF($B$7:$B$256,B23,$I$7:$I$256)>INDEX($O$58:$O$88,DAY(B23))),"Day over "&INDEX($O$58:$O$88,DAY(B23))&" h","✓"))))))))) | W23: =IF(Projects!B21="","",Projects!B21) | X23: =IF(W23="",0,SUMIFS($I$7:$I$256,$D$7:$D$256,W23,$H$7:$H$256,"NTIME")) -> 0 | Y23: =IF(W23="",0,SUMIFS($I$7:$I$256,$D$7:$D$256,W23,$H$7:$H$256,"P6")) -> 0 | Z23: =X23+Y23 -> 0 | AA23: =IF(Z23>0,Z23+(201-17)/10^6,0) -> 0
C24: =IF(B24="","",TEXT(B24,"ddd")) | E24: =IF(D24="","",IFERROR(INDEX(ProjNumbers,MATCH(D24,ProjNames,0)),"")) | F24: =IF(D24="","",IFERROR(INDEX(ProjCodes,MATCH(D24,ProjNames,0)),"")) | J24: =IF(COUNTA(B24,D24,G24,H24,I24)=0,"",IF(B24="","Enter date",IF(OR(B24<$AC$2,B24>$AC$3),"Date not in January",IF(D24="","Pick project",IF(ISNA(MATCH(D24,ProjNames,0)),"Project not in list",IF(G24="","Add task description",IF(H24="","Pick NTIME or P6",IF(N(I24)<=0,"Enter hours",IF(AND(AllowOT<>"Yes",SUMIF($B$7:$B$256,B24,$I$7:$I$256)>INDEX($O$58:$O$88,DAY(B24))),"Day over "&INDEX($O$58:$O$88,DAY(B24))&" h","✓"))))))))) | W24: =IF(Projects!B22="","",Projects!B22) | X24: =IF(W24="",0,SUMIFS($I$7:$I$256,$D$7:$D$256,W24,$H$7:$H$256,"NTIME")) -> 0 | Y24: =IF(W24="",0,SUMIFS($I$7:$I$256,$D$7:$D$256,W24,$H$7:$H$256,"P6")) -> 0 | Z24: =X24+Y24 -> 0 | AA24: =IF(Z24>0,Z24+(201-18)/10^6,0) -> 0
C25: =IF(B25="","",TEXT(B25,"ddd")) | E25: =IF(D25="","",IFERROR(INDEX(ProjNumbers,MATCH(D25,ProjNames,0)),"")) | F25: =IF(D25="","",IFERROR(INDEX(ProjCodes,MATCH(D25,ProjNames,0)),"")) | J25: =IF(COUNTA(B25,D25,G25,H25,I25)=0,"",IF(B25="","Enter date",IF(OR(B25<$AC$2,B25>$AC$3),"Date not in January",IF(D25="","Pick project",IF(ISNA(MATCH(D25,ProjNames,0)),"Project not in list",IF(G25="","Add task description",IF(H25="","Pick NTIME or P6",IF(N(I25)<=0,"Enter hours",IF(AND(AllowOT<>"Yes",SUMIF($B$7:$B$256,B25,$I$7:$I$256)>INDEX($O$58:$O$88,DAY(B25))),"Day over "&INDEX($O$58:$O$88,DAY(B25))&" h","✓"))))))))) | W25: =IF(Projects!B23="","",Projects!B23) | X25: =IF(W25="",0,SUMIFS($I$7:$I$256,$D$7:$D$256,W25,$H$7:$H$256,"NTIME")) -> 0 | Y25: =IF(W25="",0,SUMIFS($I$7:$I$256,$D$7:$D$256,W25,$H$7:$H$256,"P6")) -> 0 | Z25: =X25+Y25 -> 0 | AA25: =IF(Z25>0,Z25+(201-19)/10^6,0) -> 0
C26: =IF(B26="","",TEXT(B26,"ddd")) | E26: =IF(D26="","",IFERROR(INDEX(ProjNumbers,MATCH(D26,ProjNames,0)),"")) | F26: =IF(D26="","",IFERROR(INDEX(ProjCodes,MATCH(D26,ProjNames,0)),"")) | J26: =IF(COUNTA(B26,D26,G26,H26,I26)=0,"",IF(B26="","Enter date",IF(OR(B26<$AC$2,B26>$AC$3),"Date not in January",IF(D26="","Pick project",IF(ISNA(MATCH(D26,ProjNames,0)),"Project not in list",IF(G26="","Add task description",IF(H26="","Pick NTIME or P6",IF(N(I26)<=0,"Enter hours",IF(AND(AllowOT<>"Yes",SUMIF($B$7:$B$256,B26,$I$7:$I$256)>INDEX($O$58:$O$88,DAY(B26))),"Day over "&INDEX($O$58:$O$88,DAY(B26))&" h","✓"))))))))) | W26: =IF(Projects!B24="","",Projects!B24) | X26: =IF(W26="",0,SUMIFS($I$7:$I$256,$D$7:$D$256,W26,$H$7:$H$256,"NTIME")) -> 0 | Y26: =IF(W26="",0,SUMIFS($I$7:$I$256,$D$7:$D$256,W26,$H$7:$H$256,"P6")) -> 0 | Z26: =X26+Y26 -> 0 | AA26: =IF(Z26>0,Z26+(201-20)/10^6,0) -> 0
C27: =IF(B27="","",TEXT(B27,"ddd")) | E27: =IF(D27="","",IFERROR(INDEX(ProjNumbers,MATCH(D27,ProjNames,0)),"")) | F27: =IF(D27="","",IFERROR(INDEX(ProjCodes,MATCH(D27,ProjNames,0)),"")) | J27: =IF(COUNTA(B27,D27,G27,H27,I27)=0,"",IF(B27="","Enter date",IF(OR(B27<$AC$2,B27>$AC$3),"Date not in January",IF(D27="","Pick project",IF(ISNA(MATCH(D27,ProjNames,0)),"Project not in list",IF(G27="","Add task description",IF(H27="","Pick NTIME or P6",IF(N(I27)<=0,"Enter hours",IF(AND(AllowOT<>"Yes",SUMIF($B$7:$B$256,B27,$I$7:$I$256)>INDEX($O$58:$O$88,DAY(B27))),"Day over "&INDEX($O$58:$O$88,DAY(B27))&" h","✓"))))))))) | W27: =IF(Projects!B25="","",Projects!B25) | X27: =IF(W27="",0,SUMIFS($I$7:$I$256,$D$7:$D$256,W27,$H$7:$H$256,"NTIME")) -> 0 | Y27: =IF(W27="",0,SUMIFS($I$7:$I$256,$D$7:$D$256,W27,$H$7:$H$256,"P6")) -> 0 | Z27: =X27+Y27 -> 0 | AA27: =IF(Z27>0,Z27+(201-21)/10^6,0) -> 0
C28: =IF(B28="","",TEXT(B28,"ddd")) | E28: =IF(D28="","",IFERROR(INDEX(ProjNumbers,MATCH(D28,ProjNames,0)),"")) | F28: =IF(D28="","",IFERROR(INDEX(ProjCodes,MATCH(D28,ProjNames,0)),"")) | J28: =IF(COUNTA(B28,D28,G28,H28,I28)=0,"",IF(B28="","Enter date",IF(OR(B28<$AC$2,B28>$AC$3),"Date not in January",IF(D28="","Pick project",IF(ISNA(MATCH(D28,ProjNames,0)),"Project not in list",IF(G28="","Add task description",IF(H28="","Pick NTIME or P6",IF(N(I28)<=0,"Enter hours",IF(AND(AllowOT<>"Yes",SUMIF($B$7:$B$256,B28,$I$7:$I$256)>INDEX($O$58:$O$88,DAY(B28))),"Day over "&INDEX($O$58:$O$88,DAY(B28))&" h","✓"))))))))) | W28: =IF(Projects!B26="","",Projects!B26) | X28: =IF(W28="",0,SUMIFS($I$7:$I$256,$D$7:$D$256,W28,$H$7:$H$256,"NTIME")) -> 0 | Y28: =IF(W28="",0,SUMIFS($I$7:$I$256,$D$7:$D$256,W28,$H$7:$H$256,"P6")) -> 0 | Z28: =X28+Y28 -> 0 | AA28: =IF(Z28>0,Z28+(201-22)/10^6,0) -> 0
C29: =IF(B29="","",TEXT(B29,"ddd")) | E29: =IF(D29="","",IFERROR(INDEX(ProjNumbers,MATCH(D29,ProjNames,0)),"")) | F29: =IF(D29="","",IFERROR(INDEX(ProjCodes,MATCH(D29,ProjNames,0)),"")) | J29: =IF(COUNTA(B29,D29,G29,H29,I29)=0,"",IF(B29="","Enter date",IF(OR(B29<$AC$2,B29>$AC$3),"Date not in January",IF(D29="","Pick project",IF(ISNA(MATCH(D29,ProjNames,0)),"Project not in list",IF(G29="","Add task description",IF(H29="","Pick NTIME or P6",IF(N(I29)<=0,"Enter hours",IF(AND(AllowOT<>"Yes",SUMIF($B$7:$B$256,B29,$I$7:$I$256)>INDEX($O$58:$O$88,DAY(B29))),"Day over "&INDEX($O$58:$O$88,DAY(B29))&" h","✓"))))))))) | W29: =IF(Projects!B27="","",Projects!B27) | X29: =IF(W29="",0,SUMIFS($I$7:$I$256,$D$7:$D$256,W29,$H$7:$H$256,"NTIME")) -> 0 | Y29: =IF(W29="",0,SUMIFS($I$7:$I$256,$D$7:$D$256,W29,$H$7:$H$256,"P6")) -> 0 | Z29: =X29+Y29 -> 0 | AA29: =IF(Z29>0,Z29+(201-23)/10^6,0) -> 0
C30: =IF(B30="","",TEXT(B30,"ddd")) | E30: =IF(D30="","",IFERROR(INDEX(ProjNumbers,MATCH(D30,ProjNames,0)),"")) | F30: =IF(D30="","",IFERROR(INDEX(ProjCodes,MATCH(D30,ProjNames,0)),"")) | J30: =IF(COUNTA(B30,D30,G30,H30,I30)=0,"",IF(B30="","Enter date",IF(OR(B30<$AC$2,B30>$AC$3),"Date not in January",IF(D30="","Pick project",IF(ISNA(MATCH(D30,ProjNames,0)),"Project not in list",IF(G30="","Add task description",IF(H30="","Pick NTIME or P6",IF(N(I30)<=0,"Enter hours",IF(AND(AllowOT<>"Yes",SUMIF($B$7:$B$256,B30,$I$7:$I$256)>INDEX($O$58:$O$88,DAY(B30))),"Day over "&INDEX($O$58:$O$88,DAY(B30))&" h","✓"))))))))) | W30: =IF(Projects!B28="","",Projects!B28) | X30: =IF(W30="",0,SUMIFS($I$7:$I$256,$D$7:$D$256,W30,$H$7:$H$256,"NTIME")) -> 0 | Y30: =IF(W30="",0,SUMIFS($I$7:$I$256,$D$7:$D$256,W30,$H$7:$H$256,"P6")) -> 0 | Z30: =X30+Y30 -> 0 | AA30: =IF(Z30>0,Z30+(201-24)/10^6,0) -> 0
C31: =IF(B31="","",TEXT(B31,"ddd")) | E31: =IF(D31="","",IFERROR(INDEX(ProjNumbers,MATCH(D31,ProjNames,0)),"")) | F31: =IF(D31="","",IFERROR(INDEX(ProjCodes,MATCH(D31,ProjNames,0)),"")) | J31: =IF(COUNTA(B31,D31,G31,H31,I31)=0,"",IF(B31="","Enter date",IF(OR(B31<$AC$2,B31>$AC$3),"Date not in January",IF(D31="","Pick project",IF(ISNA(MATCH(D31,ProjNames,0)),"Project not in list",IF(G31="","Add task description",IF(H31="","Pick NTIME or P6",IF(N(I31)<=0,"Enter hours",IF(AND(AllowOT<>"Yes",SUMIF($B$7:$B$256,B31,$I$7:$I$256)>INDEX($O$58:$O$88,DAY(B31))),"Day over "&INDEX($O$58:$O$88,DAY(B31))&" h","✓"))))))))) | W31: =IF(Projects!B29="","",Projects!B29) | X31: =IF(W31="",0,SUMIFS($I$7:$I$256,$D$7:$D$256,W31,$H$7:$H$256,"NTIME")) -> 0 | Y31: =IF(W31="",0,SUMIFS($I$7:$I$256,$D$7:$D$256,W31,$H$7:$H$256,"P6")) -> 0 | Z31: =X31+Y31 -> 0 | AA31: =IF(Z31>0,Z31+(201-25)/10^6,0) -> 0
C32: =IF(B32="","",TEXT(B32,"ddd")) | E32: =IF(D32="","",IFERROR(INDEX(ProjNumbers,MATCH(D32,ProjNames,0)),"")) | F32: =IF(D32="","",IFERROR(INDEX(ProjCodes,MATCH(D32,ProjNames,0)),"")) | J32: =IF(COUNTA(B32,D32,G32,H32,I32)=0,"",IF(B32="","Enter date",IF(OR(B32<$AC$2,B32>$AC$3),"Date not in January",IF(D32="","Pick project",IF(ISNA(MATCH(D32,ProjNames,0)),"Project not in list",IF(G32="","Add task description",IF(H32="","Pick NTIME or P6",IF(N(I32)<=0,"Enter hours",IF(AND(AllowOT<>"Yes",SUMIF($B$7:$B$256,B32,$I$7:$I$256)>INDEX($O$58:$O$88,DAY(B32))),"Day over "&INDEX($O$58:$O$88,DAY(B32))&" h","✓"))))))))) | W32: =IF(Projects!B30="","",Projects!B30) | X32: =IF(W32="",0,SUMIFS($I$7:$I$256,$D$7:$D$256,W32,$H$7:$H$256,"NTIME")) -> 0 | Y32: =IF(W32="",0,SUMIFS($I$7:$I$256,$D$7:$D$256,W32,$H$7:$H$256,"P6")) -> 0 | Z32: =X32+Y32 -> 0 | AA32: =IF(Z32>0,Z32+(201-26)/10^6,0) -> 0
C33: =IF(B33="","",TEXT(B33,"ddd")) | E33: =IF(D33="","",IFERROR(INDEX(ProjNumbers,MATCH(D33,ProjNames,0)),"")) | F33: =IF(D33="","",IFERROR(INDEX(ProjCodes,MATCH(D33,ProjNames,0)),"")) | J33: =IF(COUNTA(B33,D33,G33,H33,I33)=0,"",IF(B33="","Enter date",IF(OR(B33<$AC$2,B33>$AC$3),"Date not in January",IF(D33="","Pick project",IF(ISNA(MATCH(D33,ProjNames,0)),"Project not in list",IF(G33="","Add task description",IF(H33="","Pick NTIME or P6",IF(N(I33)<=0,"Enter hours",IF(AND(AllowOT<>"Yes",SUMIF($B$7:$B$256,B33,$I$7:$I$256)>INDEX($O$58:$O$88,DAY(B33))),"Day over "&INDEX($O$58:$O$88,DAY(B33))&" h","✓"))))))))) | W33: =IF(Projects!B31="","",Projects!B31) | X33: =IF(W33="",0,SUMIFS($I$7:$I$256,$D$7:$D$256,W33,$H$7:$H$256,"NTIME")) -> 0 | Y33: =IF(W33="",0,SUMIFS($I$7:$I$256,$D$7:$D$256,W33,$H$7:$H$256,"P6")) -> 0 | Z33: =X33+Y33 -> 0 | AA33: =IF(Z33>0,Z33+(201-27)/10^6,0) -> 0
C34: =IF(B34="","",TEXT(B34,"ddd")) | E34: =IF(D34="","",IFERROR(INDEX(ProjNumbers,MATCH(D34,ProjNames,0)),"")) | F34: =IF(D34="","",IFERROR(INDEX(ProjCodes,MATCH(D34,ProjNames,0)),"")) | J34: =IF(COUNTA(B34,D34,G34,H34,I34)=0,"",IF(B34="","Enter date",IF(OR(B34<$AC$2,B34>$AC$3),"Date not in January",IF(D34="","Pick project",IF(ISNA(MATCH(D34,ProjNames,0)),"Project not in list",IF(G34="","Add task description",IF(H34="","Pick NTIME or P6",IF(N(I34)<=0,"Enter hours",IF(AND(AllowOT<>"Yes",SUMIF($B$7:$B$256,B34,$I$7:$I$256)>INDEX($O$58:$O$88,DAY(B34))),"Day over "&INDEX($O$58:$O$88,DAY(B34))&" h","✓"))))))))) | W34: =IF(Projects!B32="","",Projects!B32) | X34: =IF(W34="",0,SUMIFS($I$7:$I$256,$D$7:$D$256,W34,$H$7:$H$256,"NTIME")) -> 0 | Y34: =IF(W34="",0,SUMIFS($I$7:$I$256,$D$7:$D$256,W34,$H$7:$H$256,"P6")) -> 0 | Z34: =X34+Y34 -> 0 | AA34: =IF(Z34>0,Z34+(201-28)/10^6,0) -> 0
C35: =IF(B35="","",TEXT(B35,"ddd")) | E35: =IF(D35="","",IFERROR(INDEX(ProjNumbers,MATCH(D35,ProjNames,0)),"")) | F35: =IF(D35="","",IFERROR(INDEX(ProjCodes,MATCH(D35,ProjNames,0)),"")) | J35: =IF(COUNTA(B35,D35,G35,H35,I35)=0,"",IF(B35="","Enter date",IF(OR(B35<$AC$2,B35>$AC$3),"Date not in January",IF(D35="","Pick project",IF(ISNA(MATCH(D35,ProjNames,0)),"Project not in list",IF(G35="","Add task description",IF(H35="","Pick NTIME or P6",IF(N(I35)<=0,"Enter hours",IF(AND(AllowOT<>"Yes",SUMIF($B$7:$B$256,B35,$I$7:$I$256)>INDEX($O$58:$O$88,DAY(B35))),"Day over "&INDEX($O$58:$O$88,DAY(B35))&" h","✓"))))))))) | L35: PROJECTS THIS MONTH | W35: =IF(Projects!B33="","",Projects!B33) | X35: =IF(W35="",0,SUMIFS($I$7:$I$256,$D$7:$D$256,W35,$H$7:$H$256,"NTIME")) -> 0 | Y35: =IF(W35="",0,SUMIFS($I$7:$I$256,$D$7:$D$256,W35,$H$7:$H$256,"P6")) -> 0 | Z35: =X35+Y35 -> 0 | AA35: =IF(Z35>0,Z35+(201-29)/10^6,0) -> 0
C36: =IF(B36="","",TEXT(B36,"ddd")) | E36: =IF(D36="","",IFERROR(INDEX(ProjNumbers,MATCH(D36,ProjNames,0)),"")) | F36: =IF(D36="","",IFERROR(INDEX(ProjCodes,MATCH(D36,ProjNames,0)),"")) | J36: =IF(COUNTA(B36,D36,G36,H36,I36)=0,"",IF(B36="","Enter date",IF(OR(B36<$AC$2,B36>$AC$3),"Date not in January",IF(D36="","Pick project",IF(ISNA(MATCH(D36,ProjNames,0)),"Project not in list",IF(G36="","Add task description",IF(H36="","Pick NTIME or P6",IF(N(I36)<=0,"Enter hours",IF(AND(AllowOT<>"Yes",SUMIF($B$7:$B$256,B36,$I$7:$I$256)>INDEX($O$58:$O$88,DAY(B36))),"Day over "&INDEX($O$58:$O$88,DAY(B36))&" h","✓"))))))))) | L36: Project | M36: Project Number | N36: Oracle Code | O36: NTIME | P36: P6 | Q36: Total | R36: % of month | W36: =IF(Projects!B34="","",Projects!B34) | X36: =IF(W36="",0,SUMIFS($I$7:$I$256,$D$7:$D$256,W36,$H$7:$H$256,"NTIME")) -> 0 | Y36: =IF(W36="",0,SUMIFS($I$7:$I$256,$D$7:$D$256,W36,$H$7:$H$256,"P6")) -> 0 | Z36: =X36+Y36 -> 0 | AA36: =IF(Z36>0,Z36+(201-30)/10^6,0) -> 0
C37: =IF(B37="","",TEXT(B37,"ddd")) | E37: =IF(D37="","",IFERROR(INDEX(ProjNumbers,MATCH(D37,ProjNames,0)),"")) | F37: =IF(D37="","",IFERROR(INDEX(ProjCodes,MATCH(D37,ProjNames,0)),"")) | J37: =IF(COUNTA(B37,D37,G37,H37,I37)=0,"",IF(B37="","Enter date",IF(OR(B37<$AC$2,B37>$AC$3),"Date not in January",IF(D37="","Pick project",IF(ISNA(MATCH(D37,ProjNames,0)),"Project not in list",IF(G37="","Add task description",IF(H37="","Pick NTIME or P6",IF(N(I37)<=0,"Enter hours",IF(AND(AllowOT<>"Yes",SUMIF($B$7:$B$256,B37,$I$7:$I$256)>INDEX($O$58:$O$88,DAY(B37))),"Day over "&INDEX($O$58:$O$88,DAY(B37))&" h","✓"))))))))) | L37: =IF($AD37=0,"",INDEX($W$7:$W$206,$AD37)) | M37: =IF($AD37=0,"",INDEX(ProjNumbers,$AD37)) | N37: =IF($AD37=0,"",INDEX(ProjCodes,$AD37)) | O37: =IF($AD37=0,"",INDEX($X$7:$X$206,$AD37)) | P37: =IF($AD37=0,"",INDEX($Y$7:$Y$206,$AD37)) | Q37: =IF($AD37=0,"",INDEX($Z$7:$Z$206,$AD37)) | R37: =IF(OR($AD37=0,$L$5=0),"",Q37/$L$5) | W37: =IF(Projects!B35="","",Projects!B35) | X37: =IF(W37="",0,SUMIFS($I$7:$I$256,$D$7:$D$256,W37,$H$7:$H$256,"NTIME")) -> 0 | Y37: =IF(W37="",0,SUMIFS($I$7:$I$256,$D$7:$D$256,W37,$H$7:$H$256,"P6")) -> 0 | Z37: =X37+Y37 -> 0 | AA37: =IF(Z37>0,Z37+(201-31)/10^6,0) -> 0 | AD37: =IF(LARGE($AA$7:$AA$206,1)<=0,0,MATCH(LARGE($AA$7:$AA$206,1),$AA$7:$AA$206,0)) -> 0
C38: =IF(B38="","",TEXT(B38,"ddd")) | E38: =IF(D38="","",IFERROR(INDEX(ProjNumbers,MATCH(D38,ProjNames,0)),"")) | F38: =IF(D38="","",IFERROR(INDEX(ProjCodes,MATCH(D38,ProjNames,0)),"")) | J38: =IF(COUNTA(B38,D38,G38,H38,I38)=0,"",IF(B38="","Enter date",IF(OR(B38<$AC$2,B38>$AC$3),"Date not in January",IF(D38="","Pick project",IF(ISNA(MATCH(D38,ProjNames,0)),"Project not in list",IF(G38="","Add task description",IF(H38="","Pick NTIME or P6",IF(N(I38)<=0,"Enter hours",IF(AND(AllowOT<>"Yes",SUMIF($B$7:$B$256,B38,$I$7:$I$256)>INDEX($O$58:$O$88,DAY(B38))),"Day over "&INDEX($O$58:$O$88,DAY(B38))&" h","✓"))))))))) | L38: =IF($AD38=0,"",INDEX($W$7:$W$206,$AD38)) | M38: =IF($AD38=0,"",INDEX(ProjNumbers,$AD38)) | N38: =IF($AD38=0,"",INDEX(ProjCodes,$AD38)) | O38: =IF($AD38=0,"",INDEX($X$7:$X$206,$AD38)) | P38: =IF($AD38=0,"",INDEX($Y$7:$Y$206,$AD38)) | Q38: =IF($AD38=0,"",INDEX($Z$7:$Z$206,$AD38)) | R38: =IF(OR($AD38=0,$L$5=0),"",Q38/$L$5) | W38: =IF(Projects!B36="","",Projects!B36) | X38: =IF(W38="",0,SUMIFS($I$7:$I$256,$D$7:$D$256,W38,$H$7:$H$256,"NTIME")) -> 0 | Y38: =IF(W38="",0,SUMIFS($I$7:$I$256,$D$7:$D$256,W38,$H$7:$H$256,"P6")) -> 0 | Z38: =X38+Y38 -> 0 | AA38: =IF(Z38>0,Z38+(201-32)/10^6,0) -> 0 | AD38: =IF(LARGE($AA$7:$AA$206,2)<=0,0,MATCH(LARGE($AA$7:$AA$206,2),$AA$7:$AA$206,0)) -> 0
C39: =IF(B39="","",TEXT(B39,"ddd")) | E39: =IF(D39="","",IFERROR(INDEX(ProjNumbers,MATCH(D39,ProjNames,0)),"")) | F39: =IF(D39="","",IFERROR(INDEX(ProjCodes,MATCH(D39,ProjNames,0)),"")) | J39: =IF(COUNTA(B39,D39,G39,H39,I39)=0,"",IF(B39="","Enter date",IF(OR(B39<$AC$2,B39>$AC$3),"Date not in January",IF(D39="","Pick project",IF(ISNA(MATCH(D39,ProjNames,0)),"Project not in list",IF(G39="","Add task description",IF(H39="","Pick NTIME or P6",IF(N(I39)<=0,"Enter hours",IF(AND(AllowOT<>"Yes",SUMIF($B$7:$B$256,B39,$I$7:$I$256)>INDEX($O$58:$O$88,DAY(B39))),"Day over "&INDEX($O$58:$O$88,DAY(B39))&" h","✓"))))))))) | L39: =IF($AD39=0,"",INDEX($W$7:$W$206,$AD39)) | M39: =IF($AD39=0,"",INDEX(ProjNumbers,$AD39)) | N39: =IF($AD39=0,"",INDEX(ProjCodes,$AD39)) | O39: =IF($AD39=0,"",INDEX($X$7:$X$206,$AD39)) | P39: =IF($AD39=0,"",INDEX($Y$7:$Y$206,$AD39)) | Q39: =IF($AD39=0,"",INDEX($Z$7:$Z$206,$AD39)) | R39: =IF(OR($AD39=0,$L$5=0),"",Q39/$L$5) | W39: =IF(Projects!B37="","",Projects!B37) | X39: =IF(W39="",0,SUMIFS($I$7:$I$256,$D$7:$D$256,W39,$H$7:$H$256,"NTIME")) -> 0 | Y39: =IF(W39="",0,SUMIFS($I$7:$I$256,$D$7:$D$256,W39,$H$7:$H$256,"P6")) -> 0 | Z39: =X39+Y39 -> 0 | AA39: =IF(Z39>0,Z39+(201-33)/10^6,0) -> 0 | AD39: =IF(LARGE($AA$7:$AA$206,3)<=0,0,MATCH(LARGE($AA$7:$AA$206,3),$AA$7:$AA$206,0)) -> 0
C40: =IF(B40="","",TEXT(B40,"ddd")) | E40: =IF(D40="","",IFERROR(INDEX(ProjNumbers,MATCH(D40,ProjNames,0)),"")) | F40: =IF(D40="","",IFERROR(INDEX(ProjCodes,MATCH(D40,ProjNames,0)),"")) | J40: =IF(COUNTA(B40,D40,G40,H40,I40)=0,"",IF(B40="","Enter date",IF(OR(B40<$AC$2,B40>$AC$3),"Date not in January",IF(D40="","Pick project",IF(ISNA(MATCH(D40,ProjNames,0)),"Project not in list",IF(G40="","Add task description",IF(H40="","Pick NTIME or P6",IF(N(I40)<=0,"Enter hours",IF(AND(AllowOT<>"Yes",SUMIF($B$7:$B$256,B40,$I$7:$I$256)>INDEX($O$58:$O$88,DAY(B40))),"Day over "&INDEX($O$58:$O$88,DAY(B40))&" h","✓"))))))))) | L40: =IF($AD40=0,"",INDEX($W$7:$W$206,$AD40)) | M40: =IF($AD40=0,"",INDEX(ProjNumbers,$AD40)) | N40: =IF($AD40=0,"",INDEX(ProjCodes,$AD40)) | O40: =IF($AD40=0,"",INDEX($X$7:$X$206,$AD40)) | P40: =IF($AD40=0,"",INDEX($Y$7:$Y$206,$AD40)) | Q40: =IF($AD40=0,"",INDEX($Z$7:$Z$206,$AD40)) | R40: =IF(OR($AD40=0,$L$5=0),"",Q40/$L$5) | W40: =IF(Projects!B38="","",Projects!B38) | X40: =IF(W40="",0,SUMIFS($I$7:$I$256,$D$7:$D$256,W40,$H$7:$H$256,"NTIME")) -> 0 | Y40: =IF(W40="",0,SUMIFS($I$7:$I$256,$D$7:$D$256,W40,$H$7:$H$256,"P6")) -> 0 | Z40: =X40+Y40 -> 0 | AA40: =IF(Z40>0,Z40+(201-34)/10^6,0) -> 0 | AD40: =IF(LARGE($AA$7:$AA$206,4)<=0,0,MATCH(LARGE($AA$7:$AA$206,4),$AA$7:$AA$206,0)) -> 0
...

Sheet February
B1: February 2026 | AC1: Helpers
B2: Add one row per task in the Entry log. Everything on the right updates automatically. | AC2: 46054
B3: ENTRY LOG | L3: MONTH SUMMARY | AC3: 46081
L4: Total hours | M4: =IF(OHSystem="NTIME","NTIME (incl. overhead)","NTIME") -> NTIME | N4: =IF(OHSystem="P6","P6 (incl. overhead)","P6") -> P6 | O4: Overhead | P4: Overtime | Q4: Utilisation | R4: Days logged | S4: Days not logged | AC4: =AC2-MOD(WEEKDAY(AC2,2)-WeekStartNum,7) -> 46048
L5: =SUM($T$58:$T$85) -> 0 | M5: =SUM($P$58:$P$85)+IF(OHSystem="NTIME",SUM($R$58:$R$85),0) -> 0 | N5: =SUM($Q$58:$Q$85)+IF(OHSystem="P6",SUM($R$58:$R$85),0) -> 0 | O5: =SUM($R$58:$R$85) -> 0 | P5: =SUM($S$58:$S$85) -> 0 | Q5: =IF(L5=0,"-",(SUM($P$58:$P$85)+SUM($Q$58:$Q$85))/L5) -> - | R5: =SUMPRODUCT(($N$58:$N$85="Working")*(($P$58:$P$85+$Q$58:$Q$85)>0))+COUNTIF($N$58:$N$85,"Overhead only") -> 0 | S5: =COUNTIF($U$58:$U$85,"Not logged") -> 20
B6: Date | C6: Day | D6: Project Name | E6: Project Number | F6: Oracle Code | G6: Task Description | H6: System | I6: Hours | J6: Check
C7: =IF(B7="","",TEXT(B7,"ddd")) | E7: =IF(D7="","",IFERROR(INDEX(ProjNumbers,MATCH(D7,ProjNames,0)),"")) | F7: =IF(D7="","",IFERROR(INDEX(ProjCodes,MATCH(D7,ProjNames,0)),"")) | J7: =IF(COUNTA(B7,D7,G7,H7,I7)=0,"",IF(B7="","Enter date",IF(OR(B7<$AC$2,B7>$AC$3),"Date not in February",IF(D7="","Pick project",IF(ISNA(MATCH(D7,ProjNames,0)),"Project not in list",IF(G7="","Add task description",IF(H7="","Pick NTIME or P6",IF(N(I7)<=0,"Enter hours",IF(AND(AllowOT<>"Yes",SUMIF($B$7:$B$256,B7,$I$7:$I$256)>INDEX($O$58:$O$85,DAY(B7))),"Day over "&INDEX($O$58:$O$85,DAY(B7))&" h","✓"))))))))) | W7: =IF(Projects!B5="","",Projects!B5) -> Project A | X7: =IF(W7="",0,SUMIFS($I$7:$I$256,$D$7:$D$256,W7,$H$7:$H$256,"NTIME")) -> 0 | Y7: =IF(W7="",0,SUMIFS($I$7:$I$256,$D$7:$D$256,W7,$H$7:$H$256,"P6")) -> 0 | Z7: =X7+Y7 -> 0 | AA7: =IF(Z7>0,Z7+(201-1)/10^6,0) -> 0
C8: =IF(B8="","",TEXT(B8,"ddd")) | E8: =IF(D8="","",IFERROR(INDEX(ProjNumbers,MATCH(D8,ProjNames,0)),"")) | F8: =IF(D8="","",IFERROR(INDEX(ProjCodes,MATCH(D8,ProjNames,0)),"")) | J8: =IF(COUNTA(B8,D8,G8,H8,I8)=0,"",IF(B8="","Enter date",IF(OR(B8<$AC$2,B8>$AC$3),"Date not in February",IF(D8="","Pick project",IF(ISNA(MATCH(D8,ProjNames,0)),"Project not in list",IF(G8="","Add task description",IF(H8="","Pick NTIME or P6",IF(N(I8)<=0,"Enter hours",IF(AND(AllowOT<>"Yes",SUMIF($B$7:$B$256,B8,$I$7:$I$256)>INDEX($O$58:$O$85,DAY(B8))),"Day over "&INDEX($O$58:$O$85,DAY(B8))&" h","✓"))))))))) | L8: WEEKLY SUMMARY | W8: =IF(Projects!B6="","",Projects!B6) | X8: =IF(W8="",0,SUMIFS($I$7:$I$256,$D$7:$D$256,W8,$H$7:$H$256,"NTIME")) -> 0 | Y8: =IF(W8="",0,SUMIFS($I$7:$I$256,$D$7:$D$256,W8,$H$7:$H$256,"P6")) -> 0 | Z8: =X8+Y8 -> 0 | AA8: =IF(Z8>0,Z8+(201-2)/10^6,0) -> 0
C9: =IF(B9="","",TEXT(B9,"ddd")) | E9: =IF(D9="","",IFERROR(INDEX(ProjNumbers,MATCH(D9,ProjNames,0)),"")) | F9: =IF(D9="","",IFERROR(INDEX(ProjCodes,MATCH(D9,ProjNames,0)),"")) | J9: =IF(COUNTA(B9,D9,G9,H9,I9)=0,"",IF(B9="","Enter date",IF(OR(B9<$AC$2,B9>$AC$3),"Date not in February",IF(D9="","Pick project",IF(ISNA(MATCH(D9,ProjNames,0)),"Project not in list",IF(G9="","Add task description",IF(H9="","Pick NTIME or P6",IF(N(I9)<=0,"Enter hours",IF(AND(AllowOT<>"Yes",SUMIF($B$7:$B$256,B9,$I$7:$I$256)>INDEX($O$58:$O$85,DAY(B9))),"Day over "&INDEX($O$58:$O$85,DAY(B9))&" h","✓"))))))))) | L9: Week | M9: From | N9: To | O9: NTIME | P9: P6 | Q9: Overhead | R9: Overtime | S9: Total | W9: =IF(Projects!B7="","",Projects!B7) | X9: =IF(W9="",0,SUMIFS($I$7:$I$256,$D$7:$D$256,W9,$H$7:$H$256,"NTIME")) -> 0 | Y9: =IF(W9="",0,SUMIFS($I$7:$I$256,$D$7:$D$256,W9,$H$7:$H$256,"P6")) -> 0 | Z9: =X9+Y9 -> 0 | AA9: =IF(Z9>0,Z9+(201-3)/10^6,0) -> 0 | AF9: NTIME | AG9: P6 | AH9: Overhead
C10: =IF(B10="","",TEXT(B10,"ddd")) | E10: =IF(D10="","",IFERROR(INDEX(ProjNumbers,MATCH(D10,ProjNames,0)),"")) | F10: =IF(D10="","",IFERROR(INDEX(ProjCodes,MATCH(D10,ProjNames,0)),"")) | J10: =IF(COUNTA(B10,D10,G10,H10,I10)=0,"",IF(B10="","Enter date",IF(OR(B10<$AC$2,B10>$AC$3),"Date not in February",IF(D10="","Pick project",IF(ISNA(MATCH(D10,ProjNames,0)),"Project not in list",IF(G10="","Add task description",IF(H10="","Pick NTIME or P6",IF(N(I10)<=0,"Enter hours",IF(AND(AllowOT<>"Yes",SUMIF($B$7:$B$256,B10,$I$7:$I$256)>INDEX($O$58:$O$85,DAY(B10))),"Day over "&INDEX($O$58:$O$85,DAY(B10))&" h","✓"))))))))) | L10: ="Week 1"&IF(M10="",""," ("&DAY(M10)&"–"&DAY(N10)&")") -> Week 1 (1–1) | M10: =IF($AC$4+7*0>$AC$3,"",MAX($AC$2,$AC$4+7*0)) -> 46054 | N10: =IF(M10="","",MIN($AC$3,$AC$4+7*1-1)) -> 46054 | O10: =IF($M10="","",AF10+IF(OHSystem="NTIME",AH10,0)) -> 0 | P10: =IF($M10="","",AG10+IF(OHSystem="P6",AH10,0)) -> 0 | Q10: =IF($M10="","",AH10) -> 0 | R10: =IF($M10="","",SUMIFS($S$58:$S$85,$L$58:$L$85,">="&$M10,$L$58:$L$85,"<="&$N10)) -> 0 | S10: =IF($M10="","",SUMIFS($T$58:$T$85,$L$58:$L$85,">="&$M10,$L$58:$L$85,"<="&$N10)) -> 0 | W10: =IF(Projects!B8="","",Projects!B8) | X10: =IF(W10="",0,SUMIFS($I$7:$I$256,$D$7:$D$256,W10,$H$7:$H$256,"NTIME")) -> 0 | Y10: =IF(W10="",0,SUMIFS($I$7:$I$256,$D$7:$D$256,W10,$H$7:$H$256,"P6")) -> 0 | Z10: =X10+Y10 -> 0 | AA10: =IF(Z10>0,Z10+(201-4)/10^6,0) -> 0 | AF10: =IF($M10="",0,SUMIFS($P$58:$P$85,$L$58:$L$85,">="&$M10,$L$58:$L$85,"<="&$N10)) -> 0 | AG10: =IF($M10="",0,SUMIFS($Q$58:$Q$85,$L$58:$L$85,">="&$M10,$L$58:$L$85,"<="&$N10)) -> 0 | AH10: =IF($M10="",0,SUMIFS($R$58:$R$85,$L$58:$L$85,">="&$M10,$L$58:$L$85,"<="&$N10)) -> 0
